Workbook
Name Foto: Pit_Input!$U$2
Name TeamFoto: INDEX(Pit_Input!$T:$T,MATCH(Per_Team!$A$2,Pit_Input!$C:$C,0))
Name TeamFoto2: INDEX('[1]Pit Input'!$N:$N,MATCH('[2]Per Team'!$A$2,'[1]Pit Input'!$C:$C,0))

Sheet Data_Input
A1: Scouter Initials | B1: Match Number | C1: Robot | D1: Team Number | E1: Starting Position | F1: No Show | G1: Preload | H1: Moved? | I1: Shoot | J1: Climbing | K1: PickUp Ground | L1: PickUP Human Player | M1: PickUp Depot | N1: +1 | O1: +3 | P1: +5 | Q1: Amount in Hub | R1: Defence/ to other side | S1: End Position | T1: Died? | U1: Tipped/Fell Over? | V1: Comments | W1: driver skill
A2: Anita karki | B2: 1 | C2: R1 | D2: 6479 | E2: O | F2: false | G2: true | H2: true | I2: false | J2: NA | K2: true | L2: false | M2: false | N2: 5 | O2: 3 | P2: 95 | Q2: 80 | R2: false | S2: NA | T2: false | U2: false | V2: doen goed mee | W2: 4
A3: Jippe | B3: 1 | C3: B2 | D3: 2403 | E3: D | F3: false | G3: true | H3: false | I3: false | J3: NA | K3: true | L3: false | M3: false | N3: 2 | O3: 6 | P3: 30 | Q3: 52 | R3: false | S3: NA | T3: false | U3: false | V3: A lot of shots go to far | W3: 4 | Y3: 60 | Z3: =COUNTIF(Tabel1[Team Number],Y3) -> 5
A4: LeoV | B4: 1 | C4: R3 | D4: 9091 | E4: H | F4: true | G4: false | H4: false | I4: false | J4: NA | K4: false | L4: false | M4: false | N4: 0 | O4: 0 | P4: 0 | Q4: 100 | R4: false | S4: NA | T4: false | U4: false | W4: 1 | Y4: 244 | Z4: =COUNTIF(Tabel1[Team Number],Y4) -> 9
A5: Nick | B5: 1 | C5: B3 | D5: 10114 | E5: H | F5: false | G5: true | H5: true | I5: true | J5: L1 | K5: true | L5: false | M5: false | N5: 5 | O5: 0 | P5: 35 | Q5: 60 | R5: false | S5: NA | T5: false | U5: false | V5: Fast, brings balls from Middle before picking up. Efficient for team | W5: 4 | Y5: 288 | Z5: =COUNTIF(Tabel1[Team Number],Y5) -> 7
A6: Anita Karki | B6: 2 | C6: R3 | D6: 6833 | E6: H | F6: false | G6: true | H6: true | I6: true | J6: NA | K6: true | L6: false | M6: false | N6: 0 | O6: 9 | P6: 0 | Q6: 76 | R6: true | S6: NA | T6: false | U6: false | V6: mainly pushed fuel around | W6: 4 | Y6: 698 | Z6: =COUNTIF(Tabel1[Team Number],Y6) -> 5
A7: Jippe | B7: 2 | C7: R2 | D7: 2478 | E7: D | F7: false | G7: true | H7: true | I7: false | J7: NA | K7: true | L7: false | M7: false | N7: 0 | O7: 0 | P7: 0 | Q7: 100 | R7: false | S7: A | T7: true | U7: false | V7: Died right after auto | W7: 5 | Y7: 987 | Z7: =COUNTIF(Tabel1[Team Number],Y7) -> 6
A8: LeoV | B8: 2 | C8: B3 | D8: 2662 | E8: D | F8: false | G8: false | H8: false | I8: false | J8: NA | K8: true | L8: false | M8: false | N8: 0 | O8: 0 | P8: 0 | Q8: 1 | R8: false | S8: NA | T8: false | U8: false | V8: Looks like ilthenintake broke and the they did not shoot | W8: 2 | Y8: 991 | Z8: =COUNTIF(Tabel1[Team Number],Y8) -> 8
A9: Nick | B9: 2 | C9: B1 | D9: 991 | E9: O | F9: false | G9: true | H9: true | I9: true | J9: NA | K9: true | L9: true | M9: false | N9: 1 | O9: 9 | P9: 25 | Q9: 16 | R9: false | S9: NA | T9: false | U9: false | V9: Fast, gets balls from outposts during auto, missies a lot | W9: 4 | Y9: 996 | Z9: =COUNTIF(Tabel1[Team Number],Y9) -> 4
A10: Jippe | B10: 3 | C10: R2 | D10: 3424 | E10: H | F10: false | G10: true | H10: false | I10: false | J10: NA | K10: true | L10: false | M10: false | N10: 0 | O10: 0 | P10: 0 | Q10: 100 | R10: false | S10: NA | T10: false | U10: false | W10: 5 | Y10: 1165 | Z10: =COUNTIF(Tabel1[Team Number],Y10) -> 5
A11: LeoV | B11: 3 | C11: B1 | D11: 10506 | E11: H | F11: false | G11: true | H11: false | I11: false | J11: NA | K11: true | L11: false | M11: false | N11: 0 | O11: 0 | P11: 0 | Q11: 1 | R11: false | S11: NA | T11: false | U11: false | V11: Only moved balls to the alliance zone. Intake broke down | W11: 2 | Y11: 1212 | Z11: =COUNTIF(Tabel1[Team Number],Y11) -> 3
A12: Mil g | B12: 3 | C12: B2 | D12: 9059 | E12: D | F12: false | G12: true | H12: true | I12: false | J12: NA | K12: false | L12: false | M12: false | N12: 0 | O12: 3 | P12: 0 | Q12: 1 | R12: false | S12: NA | T12: false | U12: false | V12: Got stuck on fuel, and didn»t do much during the game | W12: 3 | Y12: 1410 | Z12: =COUNTIF(Tabel1[Team Number],Y12) -> 7
A13: Nick | B13: 3 | C13: R3 | D13: 987 | E13: O | F13: false | G13: true | H13: true | I13: true | J13: NA | K13: false | L13: false | M13: false | N13: 4 | O13: 18 | P13: 140 | Q13: 42 | R13: false | S13: NA | T13: true | U13: false | V13: Great passing, fast handeling, can go over and under, shoots fast | W13: 4 | Y13: 1828 | Z13: =COUNTIF(Tabel1[Team Number],Y13) -> 6
A14: Jippe | B14: 4 | C14: R3 | D14: 8714 | E14: O | F14: false | G14: true | H14: false | I14: false | J14: NA | K14: false | L14: false | M14: false | N14: 2 | O14: 6 | P14: 10 | Q14: 23 | R14: false | S14: NA | T14: false | U14: false | W14: 3 | Y14: 2080 | Z14: =COUNTIF(Tabel1[Team Number],Y14) -> 6
A15: LeoV | B15: 4 | C15: R2 | D15: 244 | E15: H | F15: false | G15: true | H15: false | I15: true | J15: NA | K15: true | L15: false | M15: false | N15: 3 | O15: 6 | P15: 20 | Q15: 36 | R15: false | S15: NA | T15: false | U15: false | V15: Very inacuarate, messy shooting, no power. Collected slow | W15: 3 | Y15: 2122 | Z15: =COUNTIF(Tabel1[Team Number],Y15) -> 5
A16: Mil g | B16: 4 | C16: B3 | D16: 2486 | E16: D | F16: false | G16: true | H16: true | I16: true | J16: NA | K16: true | L16: false | M16: false | N16: 0 | O16: 6 | P16: 25 | Q16: 86 | R16: true | S16: NA | T16: false | U16: false | W16: 4 | Y16: 2403 | Z16: =COUNTIF(Tabel1[Team Number],Y16) -> 5
A17: Nick | B17: 4 | C17: B1 | D17: 288 | E17: O | F17: false | G17: true | H17: false | I17: true | J17: NA | K17: true | L17: false | M17: false | N17: 3 | O17: 0 | P17: 90 | Q17: 31 | R17: false | S17: NA | T17: false | U17: true | V17: Got stuck on top of the balls | W17: 3 | Y17: 2478 | Z17: =COUNTIF(Tabel1[Team Number],Y17) -> 5
A18: Jippe | B18: 5 | C18: R2 | D18: 6352 | E18: O | F18: false | G18: true | H18: true | I18: false | J18: NA | K18: true | L18: false | M18: false | N18: 0 | O18: 6 | P18: 15 | Q18: 72 | R18: false | S18: NA | T18: false | U18: false | W18: 4 | Y18: 2486 | Z18: =COUNTIF(Tabel1[Team Number],Y18) -> 4
A19: LeoV | B19: 5 | C19: B1 | D19: 3944 | E19: D | F19: false | G19: true | H19: false | I19: false | J19: NA | K19: false | L19: false | M19: false | N19: 0 | O19: 0 | P19: 0 | Q19: 1 | R19: false | S19: NA | T19: true | U19: false | W19: 3 | Y19: 2662 | Z19: =COUNTIF(Tabel1[Team Number],Y19) -> 6
A20: Maud | B20: 5 | C20: B2 | D20: 9534 | E20: O | F20: false | G20: false | H20: false | I20: false | J20: NA | K20: false | L20: false | M20: false | N20: 0 | O20: 0 | P20: 0 | Q20: 1 | R20: false | S20: NA | T20: false | U20: false | V20: Stood still and intake did not work | W20: 2 | Y20: 2840 | Z20: =COUNTIF(Tabel1[Team Number],Y20) -> 7
A21: Mil g | B21: 5 | C21: B3 | D21: 6413 | E21: H | F21: true | G21: true | H21: false | I21: false | J21: NA | K21: false | L21: false | M21: false | N21: 0 | O21: 0 | P21: 0 | Q21: 100 | R21: false | S21: NA | T21: false | U21: false | W21: 5 | Y21: 3009 | Z21: =COUNTIF(Tabel1[Team Number],Y21) -> 6
A22: Nick | B22: 5 | C22: R3 | D22: 1165 | E22: D | F22: false | G22: true | H22: false | I22: false | J22: NA | K22: true | L22: false | M22: false | N22: 0 | O22: 0 | P22: 0 | Q22: 100 | R22: false | S22: NA | T22: true | U22: false | V22: Only brought back balls pushing them | W22: 3 | Y22: 3019 | Z22: =COUNTIF(Tabel1[Team Number],Y22) -> 5
A23: Jippe | B23: 6 | C23: B1 | D23: 11176 | E23: O | F23: false | G23: true | H23: false | I23: false | J23: NA | K23: true | L23: false | M23: false | N23: 0 | O23: 0 | P23: 0 | Q23: 100 | R23: false | S23: NA | T23: true | U23: false | V23: Not moving when enabled | W23: 5 | Y23: 3216 | Z23: =COUNTIF(Tabel1[Team Number],Y23) -> 6
A24: Joep | B24: 6 | C24: B2 | D24: 8012 | E24: H | F24: false | G24: true | H24: false | I24: false | J24: NA | K24: false | L24: false | M24: false | N24: 0 | O24: 0 | P24: 0 | Q24: 100 | R24: false | S24: NA | T24: true | U24: false | W24: 3 | Y24: 3243 | Z24: =COUNTIF(Tabel1[Team Number],Y24) -> 5
A25: Mil g | B25: 6 | C25: B3 | D25: 11100 | E25: D | F25: false | G25: true | H25: true | I25: false | J25: NA | K25: false | L25: false | M25: false | N25: 0 | O25: 0 | P25: 0 | Q25: 100 | R25: false | S25: NA | T25: false | U25: false | V25: Had camera issues, turret aimed opposite side of hub, even after rotating the robot | W25: 5 | Y25: 3245 | Z25: =COUNTIF(Tabel1[Team Number],Y25) -> 5
A26: Nick | B26: 6 | C26: R2 | D26: 10980 | E26: O | F26: false | G26: true | H26: false | I26: false | J26: NA | K26: true | L26: false | M26: false | N26: 2 | O26: 6 | P26: 90 | Q26: 59 | R26: false | S26: NA | T26: false | U26: false | W26: 2 | Y26: 3424 | Z26: =COUNTIF(Tabel1[Team Number],Y26) -> 6
A27: Joep | B27: 7 | C27: B2 | D27: 9777 | E27: H | F27: false | G27: true | H27: false | I27: false | J27: NA | K27: false | L27: false | M27: false | N27: 4 | O27: 0 | P27: 0 | Q27: 25 | R27: true | S27: NA | T27: false | U27: false | W27: 3 | Y27: 3944 | Z27: =COUNTIF(Tabel1[Team Number],Y27) -> 4
A28: Mil g | B28: 7 | C28: B3 | D28: 9501 | E28: D | F28: false | G28: true | H28: true | I28: true | J28: NA | K28: true | L28: false | M28: true | N28: 0 | O28: 0 | P28: 35 | Q28: 100 | R28: false | S28: NA | T28: true | U28: false | V28: Came back from death | W28: 4 | Y28: 4146 | Z28: =COUNTIF(Tabel1[Team Number],Y28) -> 4
A29: TimoS | B29: 7 | C29: B1 | D29: 11479 | E29: O | F29: false | G29: true | H29: true | I29: true | J29: NA | K29: false | L29: false | M29: false | N29: 0 | O29: 24 | P29: 25 | Q29: 70 | R29: false | S29: NA | T29: false | U29: false | V29: Battery problems last 30 sec (Low volt.) | W29: 3 | Y29: 4731 | Z29: =COUNTIF(Tabel1[Team Number],Y29) -> 6
A30: TimoS | B30: 8 | C30: R3 | D30: 7333 | E30: D | F30: false | G30: false | H30: true | I30: false | J30: NA | K30: true | L30: false | M30: false | N30: 0 | O30: 9 | P30: 30 | Q30: 61 | R30: false | S30: NA | T30: false | U30: false | V30: Hopper broke | W30: 5 | Y30: 5933 | Z30: =COUNTIF(Tabel1[Team Number],Y30) -> 5
A31: Joep | B31: 9 | C31: B2 | D31: 3245 | E31: O | F31: false | G31: false | H31: true | I31: true | J31: NA | K31: true | L31: false | M31: false | N31: 0 | O31: 0 | P31: 55 | Q31: 95 | R31: false | S31: NA | T31: false | U31: false | W31: 5 | Y31: 6352 | Z31: =COUNTIF(Tabel1[Team Number],Y31) -> 5
A32: LeoV | B32: 9 | C32: B1 | D32: 7755 | E32: D | F32: false | G32: true | H32: false | I32: false | J32: NA | K32: true | L32: false | M32: false | N32: 0 | O32: 6 | P32: 5 | Q32: 94 | R32: false | S32: NA | T32: false | U32: false | V32: Slow did a little bit of defence in the alliance zone | W32: 2 | Y32: 6413 | Z32: =COUNTIF(Tabel1[Team Number],Y32) -> 6
A33: Maud | B33: 9 | C33: B3 | D33: 1410 | E33: D | F33: false | G33: true | H33: true | I33: true | J33: NA | K33: false | L33: false | M33: false | N33: 0 | O33: 0 | P33: 0 | Q33: 100 | R33: true | S33: NA | T33: false | U33: false | V33: Balls to Outpost pushing | W33: 5 | Y33: 6479 | Z33: =COUNTIF(Tabel1[Team Number],Y33) -> 4
A34: Joep | B34: 10 | C34: B1 | D34: 9059 | E34: D | F34: false | G34: false | H34: true | I34: false | J34: NA | K34: false | L34: false | M34: false | N34: 18 | O34: 0 | P34: 0 | Q34: 30 | R34: false | S34: NA | T34: false | U34: false | V34: Got 3 times stuck on bump | W34: 3 | Y34: 6833 | Z34: =COUNTIF(Tabel1[Team Number],Y34) -> 6
A35: LeoV | B35: 10 | C35: R3 | D35: 5933 | E35: D | F35: false | G35: true | H35: false | I35: false | K35: true | L35: false | M35: false | N35: 0 | O35: 0 | P35: 0 | Q35: 2 | R35: true | S35: NA | T35: false | U35: false | W35: 3 | Y35: 7333 | Z35: =COUNTIF(Tabel1[Team Number],Y35) -> 9
A36: Maud | B36: 10 | C36: B3 | D36: 3424 | E36: O | F36: true | G36: false | H36: false | I36: false | J36: No attempt | K36: false | L36: false | M36: false | N36: 0 | O36: 0 | P36: 0 | Q36: 100 | R36: false | S36: NA | T36: false | U36: false | W36: 5 | Y36: 7425 | Z36: =COUNTIF(Tabel1[Team Number],Y36) -> 7
A37: Mil g | B37: 10 | C37: B2 | D37: 6833 | E37: H | F37: false | G37: false | H37: true | I37: true | J37: No attempt | K37: true | L37: false | M37: false | N37: 0 | O37: 3 | P37: 20 | Q37: 100 | R37: false | S37: NA | T37: false | U37: false | W37: 5 | Y37: 7426 | Z37: =COUNTIF(Tabel1[Team Number],Y37) -> 5
A38: Anita Karki | B38: 11 | C38: B2 | D38: 6413 | E38: H | F38: false | G38: true | H38: false | I38: false | J38: NA | K38: true | L38: false | M38: false | N38: 0 | O38: 0 | P38: 0 | Q38: 1 | R38: false | S38: NA | T38: false | U38: false | V38: shooter leek niet te werken | W38: 3 | Y38: 7755 | Z38: =COUNTIF(Tabel1[Team Number],Y38) -> 6
A39: LeoV | B39: 11 | C39: R3 | D39: 9704 | E39: O | F39: false | G39: false | H39: false | I39: false | J39: NA | K39: false | L39: false | M39: false | N39: 0 | O39: 0 | P39: 0 | Q39: 1 | R39: true | S39: NA | T39: false | U39: false | V39: Juat a little defence | W39: 3 | Y39: 8012 | Z39: =COUNTIF(Tabel1[Team Number],Y39) -> 5
A40: Maud | B40: 11 | C40: R2 | D40: 996 | E40: H | F40: true | G40: false | H40: false | I40: false | J40: No attempt | K40: false | L40: false | M40: false | N40: 0 | O40: 0 | P40: 0 | Q40: 100 | R40: false | S40: NA | T40: false | U40: false | W40: 5 | Y40: 8717 | Z40: =COUNTIF(Tabel1[Team Number],Y40) -> 5
...

Sheet Scouting schema
B2: scheduled_time | C2: match_number | D2: red1 | E2: red2 | F2: red3 | G2: blue1 | H2: blue2 | I2: blue3
B3: 0.36805556 | C3: 1 | D3: 6479 | E3: 5933 | F3: 9091 | G3: 2840 | H3: 2403 | I3: 10114 | J3: 4 | K3: 4 | L3: maud | N3: 6479 | O3: 9091 | P3: 2403 | Q3: 10114 | U3: 5933 | W3: 2840 | AA3: 6479 | AB3: 5933 | AC3: 9091 | AE3: 2403 | AF3: 10114 | AH3: teams | AI3: aantal | AJ3: hoevaakgescout
B4: 0.37361111 | C4: 2 | D4: 10380 | E4: 2478 | F4: 6833 | G4: 991 | H4: 10905 | I4: 2662 | J4: 1 | L4: anita | N4: 2662 | O4: 2478 | P4: 6833 | T4: 10380 | W4: 991 | X4: 10905 | AA4: 10380 | AB4: 2478 | AC4: 6833 | AD4: 991 | AF4: 2662 | AH4: 60 | AI4: =COUNTIF($N$3:$R$85,AH4) -> 5 | AJ4: =COUNTIF($AA$3:$AF$85,AH4) -> 5 | AL4: legenda in match schema
B5: 0.37916667 | C5: 3 | D5: 9704 | E5: 3424 | F5: 987 | G5: 10506 | H5: 9059 | I5: 7426 | J5: 3 | L5: jippe | N5: 987 | O5: 10506 | P5: 9059 | Q5: 3424 | T5: 9704 | Y5: 7426 | AA5: 9704 | AB5: 3424 | AC5: 987 | AD5: 10506 | AE5: 9059 | AH5: 244 | AI5: =COUNTIF($N$3:$R$85,AH5) -> 5 | AJ5: =COUNTIF($AA$3:$AF$85,AH5) -> 6 | AL5: rood | AM5: moest wel niet gedaan
B6: 0.38472222 | C6: 4 | D6: 996 | E6: 244 l | F6: 8717 j | G6: 288 n | H6: 698 | I6: 2486 m | J6: 3 | L6: leo | N6: 8717 | O6: 288 | P6: 2486 | Q6: 244 | T6: 996 | X6: 698 | AB6: 244 | AC6: 8717 | AD6: 288 | AF6: 2486 | AH6: 288 | AI6: =COUNTIF($N$3:$R$85,AH6) -> 5 | AJ6: =COUNTIF($AA$3:$AF$85,AH6) -> 6 | AL6: groen | AM6: gedaan
B7: 0.39027778 | C7: 5 | D7: 3019 | E7: 6352 j | F7: 1165 n | G7: 3944 l | H7: 9534 ma | I7: 6413 mi | J7: 4 | N7: 6352 | O7: 1165 | P7: 3944 | Q7: 9534 | T7: 3019 | Y7: 6413 | AA7: 3019 | AB7: 6352 | AC7: 1165 | AD7: 3944 | AE7: 9534 | AF7: 6413 | AH7: 698 | AI7: =COUNTIF($N$3:$R$85,AH7) -> 5 | AJ7: =COUNTIF($AA$3:$AF$85,AH7) -> 5 | AL7: geel | AM7: moet nog
B8: 0.39583333 | C8: 6 | D8: 10988 | E8: 10980 ni | F8: 3216 | G8: 11176 ji | H8: 8012 jo | I8: 11100 mi | J8: 3 | K8: 3 | L8: timo | N8: 11176 | O8: 8012 | P8: 11100 | T8: 10988 | U8: 10980 | V8: 3216 | AB8: 10980 | AC8: 3216 | AD8: 11176 | AE8: 8012 | AF8: 11100 | AH8: 987 | AI8: =COUNTIF($N$3:$R$85,AH8) -> 4 | AJ8: =COUNTIF($AA$3:$AF$85,AH8) -> 6 | AL8: wit | AM8: niet belangrijk voor extra scouten en niet gescout
B9: 0.40138889 | C9: 7 | D9: 10183 | E9: 2122 | F9: 60 | G9: 11479 ti | H9: 9777 jo | I9: 9501 mi | J9: 2 | L9: joep | N9: 11479 | O9: 9501 | P9: 9777 | T9: 10183 | U9: 2122 | V9: 60 | AA9: 10183 | AB9: 2122 | AC9: 60 | AD9: 11479 | AE9: 9777 | AF9: 9501 | AH9: 991 | AI9: =COUNTIF($N$3:$R$85,AH9) -> 5 | AJ9: =COUNTIF($AA$3:$AF$85,AH9) -> 7
B10: 0.40694444 | C10: 8 | D10: 1212 | E10: 4731 | F10: 7333 | G10: 2080 | H10: 10933 | I10: 1828 | J10: 1 | L10: milan | N10: 1212 | O10: 2080 | P10: 7333 | X10: 10933 | Y10: 1828 | AA10: 1212 | AB10: 4731 | AC10: 7333 | AH10: 996 | AI10: =COUNTIF($N$3:$R$85,AH10) -> 5 | AJ10: =COUNTIF($AA$3:$AF$85,AH10) -> 4
B11: 0.4125 | C11: 9 | D11: 4146 | E11: 3009 | F11: 3243 | G11: 7755 | H11: 3245 jo | I11: 1410 ma | J11: 2 | N11: 3009 | O11: 1410 | P11: 3245 | T11: 4146 | V11: 3243 | W11: 7755 | AA11: 4146 | AC11: 3243 | AD11: 7755 | AE11: 3245 | AF11: 1410 | AH11: 1165 | AI11: =COUNTIF($N$3:$R$85,AH11) -> 4 | AJ11: =COUNTIF($AA$3:$AF$85,AH11) -> 4
B12: 0.41805556 | C12: 10 | D12: 5933 | E12: 7425 | F12: 2478 l | G12: 9059 jo | H12: 6833 mi | I12: 3424 ma | J12: 1 | N12: 9059 | O12: 2478 | P12: 3424 | T12: 5933 | U12: 7425 | X12: 6833 | AC12: 2478 | AD12: 9059 | AE12: 6833 | AF12: 3424 | AH12: 1212 | AI12: =COUNTIF($N$3:$R$85,AH12) -> 5 | AJ12: =COUNTIF($AA$3:$AF$85,AH12) -> 5
B13: 0.43055556 | C13: 11 | D13: 9534 | E13: 996 ma | F13: 9704 le | G13: 9091 ni | H13: 6413 a | I13: 10905 ni | J13: 2 | K13: 5 | N13: 9534 | O13: 9091 | P13: 996 | Q13: 9704 | X13: 6413 | Y13: 10905 | AA13: 9534 | AB13: 996 | AC13: 9704 | AD13: 9091 | AE13: 6413 | AF13: 10905 | AH13: 1410 | AI13: =COUNTIF($N$3:$R$85,AH13) -> 6 | AJ13: =COUNTIF($AA$3:$AF$85,AH13) -> 5
B14: 0.43611111 | C14: 12 | D14: 3944 | E14: 288 m | F14: 6479 l | G14: 244 ni | H14: 991 j | I14: 11176 an | J14: 4 | L14: maud | N14: 3944 | O14: 288 | P14: 6479 | Q14: 11176 | R14: 244 | X14: 991 | AA14: 3944 | AB14: 288 | AC14: 6479 | AD14: 244 | AE14: 991 | AF14: 11176 | AH14: 1828 | AI14: =COUNTIF($N$3:$R$85,AH14) -> 5 | AJ14: =COUNTIF($AA$3:$AF$85,AH14) -> 4
A15: kijken wie penalties had | B15: 0.44166667 | C15: 13 | D15: 2403 | E15: 2486 | F15: 10988 | G15: 1165 a | H15: 8717 l | I15: 2122 ji | J15: 5 | L15: jippe | N15: 2403 | O15: 2486 | P15: 1165 | Q15: 8717 | R15: 2122 | V15: 10988 | AA15: 2403 | AB15: 2486 | AC15: 10988 | AD15: 1165 | AE15: 8717 | AF15: 2122 | AH15: 2080 | AI15: =COUNTIF($N$3:$R$85,AH15) -> 6 | AJ15: =COUNTIF($AA$3:$AF$85,AH15) -> 3
B16: 0.44722222 | C16: 14 | D16: 10506 | E16: 10183 | F16: 8012 a | G16: 7426 l | H16: 2080 ji | I16: 3019 | J16: 2 | L16: anita | N16: 10506 | O16: 8012 | P16: 2080 | Q16: 7426 | R16: 10183 | Y16: 3019 | AA16: 10506 | AB16: 10183 | AC16: 8012 | AD16: 7426 | AE16: 2080 | AH16: 2122 | AI16: =COUNTIF($N$3:$R$85,AH16) -> 5 | AJ16: =COUNTIF($AA$3:$AF$85,AH16) -> 6
B17: 0.45277778 | C17: 15 | D17: 10114 | E17: 9501 | F17: 1212 | G17: 2662 | H17: 7333 ji | I17: 1410 | J17: 2 | L17: leo | N17: 1212 | O17: 2662 | P17: 1410 | Q17: 7333 | R17: 9501 | AA17: 10114 | AB17: 9501 | AC17: 1212 | AE17: 7333 | AH17: 2403 | AI17: =COUNTIF($N$3:$R$85,AH17) -> 5 | AJ17: =COUNTIF($AA$3:$AF$85,AH17) -> 5
B18: 0.45833333 | C18: 16 | D18: 6352 mi | E18: 7755 | F18: 4146 | G18: 10933 l | H18: 60 jo | I18: 3216 ti | J18: 2 | K18: 5 | L18: maud | N18: 6352 | O18: 7755 | P18: 3216 | Q18: 4146 | R18: 10933 | X18: 60 | AA18: 6352 | AB18: 7755 | AC18: 4146 | AE18: 60 | AF18: 3216 | AH18: 2478 | AI18: =COUNTIF($N$3:$R$85,AH18) -> 4 | AJ18: =COUNTIF($AA$3:$AF$85,AH18) -> 6
B19: 0.46388889 | C19: 17 | D19: 698 | E19: 987 | F19: 11479 | G19: 10980 | H19: 1828 | I19: 9777 ti | J19: 2 | L19: milan | N19: 987 | O19: 11479 | P19: 9777 | Q19: 10980 | T19: 698 | X19: 1828 | AA19: 698 | AB19: 987 | AC19: 11479 | AD19: 10980 | AF19: 9777 | AH19: 2486 | AI19: =COUNTIF($N$3:$R$85,AH19) -> 4 | AJ19: =COUNTIF($AA$3:$AF$85,AH19) -> 5
B20: 0.46944444 | C20: 18 | D20: 3243 | E20: 11100 | F20: 4731 | G20: 7425 le | H20: 3009 jo | I20: 2840 ti | J20: 3 | L20: joep | N20: 11100 | O20: 7425 | P20: 3009 | Q20: 2840 | R20: 4731 | T20: 3243 | AH20: 2662 | AI20: =COUNTIF($N$3:$R$85,AH20) -> 5 | AJ20: =COUNTIF($AA$3:$AF$85,AH20) -> 4
B21: 0.475 | C21: 19 | D21: 1165 | E21: 3245 | F21: 9059 | G21: 8717 | H21: 6479 | I21: 10380 | J21: 5 | L21: timo | N21: 1165 | O21: 9059 | P21: 8717 | Q21: 6479 | R21: 10380 | U21: 3245 | AH21: 2840 | AI21: =COUNTIF($N$3:$R$85,AH21) -> 5 | AJ21: =COUNTIF($AA$3:$AF$85,AH21) -> 4
B22: 0.48055556 | C22: 20 | D22: 2486 | E22: 2122 | F22: 996 | G22: 3019 | H22: 10506 | I22: 2478 | J22: 4 | L22: jippe | N22: 2486 | O22: 2122 | P22: 3019 | Q22: 10506 | R22: 996 | Y22: 2478 | AH22: 3009 | AI22: =COUNTIF($N$3:$R$85,AH22) -> 5 | AJ22: =COUNTIF($AA$3:$AF$85,AH22) -> 6
B23: 0.48611111 | C23: 21 | D23: 2662 | E23: 9091 | F23: 288 | G23: 7333 | H23: 3944 | I23: 8012 | J23: 0 | K23: 4 | L23: anita | N23: 7333 | O23: 2662 | P23: 3944 | Q23: 8012 | U23: 9091 | V23: 288 | AB23: 9091 | AC23: 288 | AD23: 7333 | AH23: 3019 | AI23: =COUNTIF($N$3:$R$85,AH23) -> 5 | AJ23: =COUNTIF($AA$3:$AF$85,AH23) -> 5
B24: 0.49166667 | C24: 22 | D24: 2403 | E24: 11176 | F24: 1212 | G24: 10183 | H24: 10905 | I24: 6833 | J24: 4 | L24: leo | N24: 2403 | O24: 11176 | P24: 1212 | Q24: 10905 | W24: 10183 | Y24: 6833 | AA24: 2403 | AB24: 11176 | AC24: 1212 | AD24: 10183 | AE24: 10905 | AF24: 6833 | AH24: 3216 | AI24: =COUNTIF($N$3:$R$85,AH24) -> 5 | AJ24: =COUNTIF($AA$3:$AF$85,AH24) -> 4
B25: 0.49722222 | C25: 23 | D25: 3216 | E25: 2080 | F25: 11479 | G25: 9501 | H25: 698 | I25: 10933 | J25: 1 | L25: maud | N25: 11479 | O25: 698 | P25: 2080 | Q25: 3216 | W25: 9501 | Y25: 10933 | AA25: 3216 | AB25: 2080 | AC25: 11479 | AD25: 9501 | AE25: 698 | AF25: 10933 | AH25: 3243 | AI25: =COUNTIF($N$3:$R$85,AH25) -> 5 | AJ25: =COUNTIF($AA$3:$AF$85,AH25) -> 6
B26: 0.54166667 | C26: 24 | D26: 6352 | E26: 9777 | F26: 2840 | G26: 1410 | H26: 10988 | I26: 3009 | J26: 2 | L26: milan | N26: 6352 | O26: 3009 | P26: 1410 | Q26: 2840 | U26: 9777 | X26: 10988 | AB26: 9777 | AC26: 2840 | AD26: 1410 | AE26: 10988 | AF26: 3009 | AH26: 3245 | AI26: =COUNTIF($N$3:$R$85,AH26) -> 5 | AJ26: =COUNTIF($AA$3:$AF$85,AH26) -> 6
B27: 0.54722222 | C27: 25 | D27: 991 | E27: 9534 | F27: 3424 | G27: 7755 | H27: 3243 | I27: 987 | J27: 4 | N27: 9534 | O27: 7755 | P27: 3243 | Q27: 987 | T27: 991 | V27: 3424 | AA27: 991 | AB27: 9534 | AC27: 3424 | AD27: 7755 | AE27: 3243 | AF27: 987 | AH27: 3424 | AI27: =COUNTIF($N$3:$R$85,AH27) -> 5 | AJ27: =COUNTIF($AA$3:$AF$85,AH27) -> 5
B28: 0.55277778 | C28: 26 | D28: 4146 | E28: 7426 | F28: 5933 | G28: 6413 | H28: 1828 | I28: 10380 | J28: 2 | K28: 3 | L28: jippe | N28: 5933 | O28: 10380 | P28: 4146 | U28: 7426 | W28: 6413 | X28: 1828 | AA28: 4146 | AB28: 7426 | AC28: 5933 | AD28: 6413 | AE28: 1828 | AF28: 10380 | AH28: 3944 | AI28: =COUNTIF($N$3:$R$85,AH28) -> 5 | AJ28: =COUNTIF($AA$3:$AF$85,AH28) -> 4
B29: 0.55833333 | C29: 27 | D29: 3245 | E29: 10114 | F29: 10980 | G29: 9704 | H29: 244 | I29: 7425 | J29: 1 | L29: joep | N29: 7425 | O29: 244 | P29: 3245 | U29: 10114 | V29: 10980 | W29: 9704 | AA29: 3245 | AB29: 10114 | AC29: 10980 | AD29: 9704 | AE29: 244 | AF29: 7425 | AH29: 4146 | AI29: =COUNTIF($N$3:$R$85,AH29) -> 5 | AJ29: =COUNTIF($AA$3:$AF$85,AH29) -> 7
B30: 0.56388889 | C30: 28 | D30: 4731 | E30: 60 | F30: 9059 | G30: 11100 | H30: 2662 | I30: 996 | J30: 3 | L30: timo | N30: 4731 | O30: 9059 | P30: 11100 | X30: 2662 | Y30: 996 | AA30: 4731 | AB30: 60 | AC30: 9059 | AD30: 11100 | AE30: 2662 | AF30: 996 | AH30: 4731 | AI30: =COUNTIF($N$3:$R$85,AH30) -> 4 | AJ30: =COUNTIF($AA$3:$AF$85,AH30) -> 4
B31: 0.56944444 | C31: 29 | D31: 11176 | E31: 11479 | F31: 7333 | G31: 1212 | H31: 1165 | I31: 10506 | J31: 0 | N31: 7333 | O31: 1212 | P31: 10506 | U31: 11479 | X31: 1165 | AA31: 11176 | AB31: 11479 | AC31: 7333 | AF31: 10506 | AH31: 5933 | AI31: =COUNTIF($N$3:$R$85,AH31) -> 5 | AJ31: =COUNTIF($AA$3:$AF$85,AH31) -> 3
B32: 0.575 | C32: 30 | D32: 6833 | E32: 9501 | F32: 2486 | G32: 10988 | H32: 3944 | I32: 9091 | J32: 2 | N32: 2486 | O32: 10988 | P32: 6833 | U32: 9501 | X32: 3944 | Y32: 9091 | AA32: 6833 | AB32: 9501 | AC32: 2486 | AH32: 6352 | AI32: =COUNTIF($N$3:$R$85,AH32) -> 4 | AJ32: =COUNTIF($AA$3:$AF$85,AH32) -> 4
B33: 0.58055556 | C33: 31 | D33: 3243 | E33: 2478 | F33: 288 | G33: 8012 | H33: 987 | I33: 2403 | J33: 3 | K33: 4 | L33: maud | N33: 3243 | O33: 987 | P33: 2403 | Q33: 2478 | V33: 288 | W33: 8012 | AA33: 3243 | AB33: 2478 | AC33: 288 | AH33: 6413 | AI33: =COUNTIF($N$3:$R$85,AH33) -> 5 | AJ33: =COUNTIF($AA$3:$AF$85,AH33) -> 6
B34: 0.58611111 | C34: 32 | D34: 698 | E34: 10183 | F34: 1410 | G34: 6413 | H34: 6479 | I34: 7755 | J34: 3 | L34: anita | N34: 6413 | O34: 6479 | P34: 7755 | Q34: 698 | U34: 10183 | V34: 1410 | AA34: 698 | AB34: 10183 | AC34: 1410 | AD34: 6413 | AE34: 6479 | AF34: 7755 | AH34: 6479 | AI34: =COUNTIF($N$3:$R$85,AH34) -> 4 | AJ34: =COUNTIF($AA$3:$AF$85,AH34) -> 4
B35: 0.59166667 | C35: 33 | D35: 10905 | E35: 1828 | F35: 3009 | G35: 244 | H35: 3019 | I35: 10980 | J35: 4 | L35: milan | N35: 10905 | O35: 1828 | P35: 3009 | Q35: 3019 | W35: 244 | Y35: 10980 | AA35: 10905 | AB35: 1828 | AC35: 3009 | AD35: 244 | AE35: 3019 | AF35: 10980 | AH35: 6833 | AI35: =COUNTIF($N$3:$R$85,AH35) -> 5 | AJ35: =COUNTIF($AA$3:$AF$85,AH35) -> 7
B36: 0.59722222 | C36: 34 | D36: 2080 | E36: 991 | F36: 6352 | G36: 5933 | H36: 11100 | I36: 3245 | J36: 4 | L36: leo | N36: 991 | O36: 6352 | P36: 5933 | Q36: 11100 | T36: 2080 | Y36: 3245 | AB36: 991 | AC36: 6352 | AD36: 5933 | AE36: 11100 | AF36: 3245 | AH36: 7333 | AI36: =COUNTIF($N$3:$R$85,AH36) -> 9 | AJ36: =COUNTIF($AA$3:$AF$85,AH36) -> 6
B37: 0.60277778 | C37: 35 | D37: 9777 | E37: 7426 | F37: 60 | G37: 9534 | H37: 7425 | I37: 3216 | J37: 3 | N37: 60 | O37: 9534 | P37: 7425 | Q37: 3216 | T37: 9777 | U37: 7426 | AB37: 7426 | AC37: 60 | AD37: 9534 | AH37: 7425 | AI37: =COUNTIF($N$3:$R$85,AH37) -> 5 | AJ37: =COUNTIF($AA$3:$AF$85,AH37) -> 3
B38: 0.60833333 | C38: 36 | D38: 4731 | E38: 3424 | F38: 8717 | G38: 2122 | H38: 4146 | I38: 10114 | J38: 2 | K38: 3 | L38: joep | N38: 8717 | O38: 2122 | P38: 3424 | T38: 4731 | X38: 4146 | Y38: 10114 | AA38: 4731 | AB38: 3424 | AC38: 8717 | AD38: 2122 | AE38: 4146 | AF38: 10114 | AH38: 7426 | AI38: =COUNTIF($N$3:$R$85,AH38) -> 5 | AJ38: =COUNTIF($AA$3:$AF$85,AH38) -> 6
B39: 0.61388889 | C39: 37 | D39: 2840 | E39: 10380 | F39: 9501 | G39: 10933 | H39: 9704 | I39: 11176 | J39: 1 | L39: jippe | N39: 10380 | O39: 2840 | P39: 9704 | V39: 9501 | W39: 10933 | Y39: 11176 | AB39: 10380 | AC39: 9501 | AD39: 10933 | AE39: 9704 | AF39: 11176 | AH39: 7755 | AI39: =COUNTIF($N$3:$R$85,AH39) -> 5 | AJ39: =COUNTIF($AA$3:$AF$85,AH39) -> 7
B40: 0.61944444 | C40: 38 | D40: 10506 | E40: 6413 | F40: 288 | G40: 9059 | H40: 3243 | I40: 1212 | J40: 3 | L40: timo | N40: 6413 | O40: 9059 | P40: 3243 | T40: 10506 | V40: 288 | Y40: 1212 | AA40: 10506 | AB40: 6413 | AC40: 288 | AD40: 9059 | AE40: 3243 | AF40: 1212 | AH40: 8012 | AI40: =COUNTIF($N$3:$R$85,AH40) -> 5 | AJ40: =COUNTIF($AA$3:$AF$85,AH40) -> 3
B41: 0.625 | C41: 39 | D41: 7755 | E41: 3019 | F41: 2403 | G41: 2478 | H41: 11479 | I41: 244 | J41: 3 | N41: 7755 | O41: 3019 | P41: 2403 | W41: 2478 | X41: 11479 | Y41: 244 | AA41: 7755 | AB41: 3019 | AC41: 2403 | AD41: 2478 | AF41: 244 | AH41: 8717 | AI41: =COUNTIF($N$3:$R$85,AH41) -> 5 | AJ41: =COUNTIF($AA$3:$AF$85,AH41) -> 5
...

Sheet Matches
A1: match_key | B1: scheduled_date | C1: scheduled_time | D1: comp_level | E1: match_number | F1: set_number | G1: red1 | H1: red2 | I1: red3 | J1: blue1 | K1: blue2 | L1: blue3 | M1: red_score | N1: blue_score
A2: 2026azfg_qm1 | B2: 46094 | C2: 0.36805556 | D2: qm | E2: 1 | F2: 1 | G2: 6479 | H2: 5933 | I2: 9091 | J2: 2840 | K2: 2403 | L2: 10114 | M2: 93 | N2: 53
A3: 2026azfg_qm2 | B3: 46094 | C3: 0.37361111 | D3: qm | E3: 2 | F3: 1 | G3: 10380 | H3: 2478 | I3: 6833 | J3: 991 | K3: 10905 | L3: 2662 | M3: 48 | N3: 32
A4: 2026azfg_qm3 | B4: 46094 | C4: 0.37916667 | D4: qm | E4: 3 | F4: 1 | G4: 9704 | H4: 3424 | I4: 987 | J4: 10506 | K4: 9059 | L4: 7426 | M4: 128 | N4: 235
A5: 2026azfg_qm4 | B5: 46094 | C5: 0.38472222 | D5: qm | E5: 4 | F5: 1 | G5: 996 | H5: 244 | I5: 8717 | J5: 288 | K5: 698 | L5: 2486 | M5: 47 | N5: 102
A6: 2026azfg_qm5 | B6: 46094 | C6: 0.39027778 | D6: qm | E6: 5 | F6: 1 | G6: 3019 | H6: 6352 | I6: 1165 | J6: 3944 | K6: 9534 | L6: 6413 | M6: 48 | N6: 16
A7: 2026azfg_qm6 | B7: 46094 | C7: 0.39583333 | D7: qm | E7: 6 | F7: 1 | G7: 10988 | H7: 10980 | I7: 3216 | J7: 11176 | K7: 8012 | L7: 11100 | M7: 122 | N7: 9
A8: 2026azfg_qm7 | B8: 46094 | C8: 0.40138889 | D8: qm | E8: 7 | F8: 1 | G8: 10183 | H8: 2122 | I8: 60 | J8: 11479 | K8: 9777 | L8: 9501 | M8: 311 | N8: 94
A9: 2026azfg_qm8 | B9: 46094 | C9: 0.40694444 | D9: qm | E9: 8 | F9: 1 | G9: 1212 | H9: 4731 | I9: 7333 | J9: 2080 | K9: 10933 | L9: 1828 | M9: 83 | N9: 33
A10: 2026azfg_qm9 | B10: 46094 | C10: 0.4125 | D10: qm | E10: 9 | F10: 1 | G10: 4146 | H10: 3009 | I10: 3243 | J10: 7755 | K10: 3245 | L10: 1410 | M10: 70 | N10: 177
A11: 2026azfg_qm10 | B11: 46094 | C11: 0.41805556 | D11: qm | E11: 10 | F11: 1 | G11: 5933 | H11: 7425 | I11: 2478 | J11: 9059 | K11: 6833 | L11: 3424 | M11: 55 | N11: 22
A12: 2026azfg_qm11 | B12: 46094 | C12: 0.43055556 | D12: qm | E12: 11 | F12: 1 | G12: 9534 | H12: 996 | I12: 9704 | J12: 9091 | K12: 6413 | L12: 10905 | M12: 14 | N12: 49
A13: 2026azfg_qm12 | B13: 46094 | C13: 0.43611111 | D13: qm | E13: 12 | F13: 1 | G13: 3944 | H13: 288 | I13: 6479 | J13: 244 | K13: 991 | L13: 11176 | M13: 109 | N13: 119
... A99: 2026azfg_f1m2 | B99: 46095 | C99: 0.70833333 | D99: f | E99: 2 | F99: 1 | G99: 2122 | H99: 7426 | I99: 7755 | J99: 1410 | K99: 3245 | L99: 6413 | M99: 372 | N99: 83

Sheet Alliances
B1: C | C1: 1e | D1: 2e | E1: 3e
A2: A1 | B2: 2122 | C2: 7426 | D2: 2478 | E2: 7755
A3: A2 | B3: 2486 | C3: 987 | D3: 4731
A4: A3 | B4: 3245 | C4: 6413 | D4: 1410
A5: A4 | B5: 6479 | C5: 9501 | D5: 7333 | E5: 60
A6: A5 | B6: 10114 | C6: 3243 | D6: 2403
A7: A6 | B7: 10980 | C7: 3216 | D7: 10933
A8: A7 | B8: 10183 | C8: 7425 | D8: 1165 | E8: 11479
A9: A8 | B9: 991 | C9: 3019 | D9: 1212

Sheet Practice day input
A1: Scouter Initials | B1: Match Number | C1: Robot | D1: Team Number | E1: Starting Position | F1: No Show | G1: Preload | H1: Moved? | I1: Shoot | J1: Climbing | K1: PickUp Ground | L1: PickUP Human Player | M1: PickUp Depot | N1: +1 | O1: +3 | P1: +5 | Q1: Amount in Hub | R1: Defence/ to other side | S1: End Position | T1: Died? | U1: Tipped/Fell Over? | V1: Comments | W1: driver skill | Y1: no show lijst
A2: Jippe | B2: 1 | C2: B2 | D2: 2122 | E2: O | F2: false | G2: true | H2: true | I2: true | J2: No attempt | K2: true | L2: false | M2: false | N2: 0 | O2: 0 | P2: 40 | Q2: 82 | R2: false | S2: NA | T2: true | U2: false | V2: Intake didn't work after auto, robot didn't lose connection but had trouble driving. Maybe CAN or swerve issue | W2: 3 | Y2: Match | Z2: team | AB2: opmerking
A3: Anita Karki | B3: 1 | C3: B3 | D3: 1165 | E3: D | F3: false | G3: true | H3: false | I3: false | J3: NA | K3: true | L3: false | M3: false | N3: 5 | O3: 15 | P3: 20 | Q3: 1 | R3: false | S3: NA | T3: false | U3: false | V3: robot got stuck, robot shoot the fuell but not in hub | W3: 2 | Y3: 1 | Z3: 996
A4: Anita Karki | B4: 2 | C4: B3 | D4: 3245 | E4: D | F4: false | G4: true | H4: true | I4: true | J4: NA | K4: true | L4: false | M4: false | N4: 0 | O4: 0 | P4: 55 | Q4: 80 | R4: true | S4: NA | T4: false | U4: false | V4: oke | W4: 4
A5: Maud m | B5: 3 | C5: B1 | D5: 991 | E5: O | F5: false | G5: true | H5: true | I5: true | J5: NA | K5: true | L5: false | M5: false | N5: 9 | O5: 15 | P5: 30 | Q5: 31 | R5: false | S5: NA | T5: false | U5: false | V5: Shooter did not work well | W5: 3
A6: Jippe | B6: 4 | C6: B2 | D6: 60 | E6: O | F6: false | G6: true | H6: false | I6: false | J6: No attempt | K6: true | L6: false | M6: false | N6: 15 | O6: 3 | P6: 0 | Q6: 11 | R6: false | S6: NA | T6: false | U6: false | W6: 2
A7: Maud M | B7: 4 | C7: B1 | D7: 1828 | E7: D | F7: false | G7: true | H7: false | I7: false | J7: No attempt | K7: true | L7: false | M7: false | N7: 0 | O7: 9 | P7: 20 | Q7: 86 | R7: false | S7: NA | T7: false | U7: false | V7: Twice stuck on bump | W7: 3
A8: Maud M | B8: 5 | C8: B1 | D8: 6413 | E8: D | F8: false | G8: true | H8: true | I8: false | J8: No attempt | K8: true | L8: false | M8: true | N8: 4 | O8: 9 | P8: 30 | Q8: 1 | R8: false | S8: NA | T8: false | U8: false | V8: Stood still end of match | W8: 4
A9: 677Nick | B9: 5 | C9: R3 | D9: 2486 | E9: D | F9: false | G9: true | H9: true | I9: false | J9: NA | K9: true | L9: false | M9: false | N9: 2 | O9: 3 | P9: 25 | Q9: 41 | R9: false | S9: NA | T9: false | U9: false | V9: Got stuck on bump, got help getting off | W9: 3
A10: LeoV | B10: 5 | C10: R1 | D10: 7425 | E10: H | F10: false | G10: true | H10: true | I10: true | J10: No attempt | K10: true | L10: false | M10: true | N10: 0 | O10: 0 | P10: 20 | Q10: 64 | R10: false | S10: NA | T10: false | U10: false | V10: Slow start shooting | W10: 4
A11: Anita Karki | B11: 5 | C11: B3 | D11: 10933 | E11: O | F11: false | G11: true | H11: false | I11: false | J11: NA | K11: false | L11: false | M11: false | N11: 0 | O11: 3 | P11: 0 | Q11: 33 | R11: true | S11: No Attempt | T11: false | U11: false | V11: deden niet intaken, schoten niet op doel, hebben klimber maar deden niet klimmen | W11: 2
A12: Joep | B12: 6 | C12: B2 | D12: 1410 | E12: O | F12: false | G12: true | H12: true | I12: true | J12: NA | K12: false | L12: false | M12: false | N12: 0 | O12: 0 | P12: 0 | Q12: 100 | R12: false | S12: NA | T12: false | U12: false | V12: Intake didn't work. | W12: 4
A13: LeoV | B13: 6 | C13: B3 | D13: 7426 | E13: O | F13: false | G13: true | H13: true | I13: false | J13: NA | K13: true | L13: true | M13: true | N13: 0 | O13: 0 | P13: 75 | Q13: 89 | R13: true | S13: A | T13: false | U13: false | V13: Fast and quick shoots anlot of balls to the alliance zone | W13: 5
A14: TimoS | B14: 6 | C14: B1 | D14: 2840 | E14: D | F14: false | G14: true | H14: false | I14: true | J14: NA | K14: true | L14: false | M14: false | N14: 0 | O14: 3 | P14: 0 | Q14: 35 | R14: false | S14: NA | T14: false | U14: false | V14: Incos. Intake, shooter missed many | W14: 3
A15: TimoS | B15: 7 | C15: B3 | D15: 7333 | E15: D | F15: false | G15: true | H15: true | I15: true | J15: NA | K15: false | L15: false | M15: fslse | N15: 0 | O15: 0 | P15: 25 | Q15: 50 | R15: false | S15: NA | T15: false | U15: false | W15: 5
A16: TimoS | B16: 8 | C16: B1 | D16: 11479 | E16: D | F16: false | G16: true | H16: true | I16: true | J16: NA | K16: true | L16: false | M16: false | N16: 0 | O16: 18 | P16: 30 | Q16: 50 | R16: false | S16: NA | T16: false | U16: false | W16: 3
A17: Joep | B17: 8 | C17: B2 | D17: 987 | E17: O | F17: false | G17: true | H17: true | I17: true | J17: NA | K17: true | L17: false | M17: false | N17: 6 | O17: 0 | P17: 0 | Q17: 80 | R17: false | S17: NA | T17: true | U17: false | W17: 4
A18: TimoS | B18: 9 | C18: B1 | D18: 9059 | E18: O | F18: false | G18: false | H18: false | I18: false | J18: NA | K18: true | L18: false | M18: false | N18: 0 | O18: 0 | P18: 0 | R18: false | S18: NA | T18: false | U18: false | V18: Incos. Intake, shooter jammer or something | W18: 3
A19: Joep | B19: 9 | C19: B2 | D19: 4731 | E19: H | F19: false | G19: true | H19: true | I19: true | J19: NA | K19: true | L19: false | M19: false | N19: 16 | O19: 0 | P19: 0 | Q19: 10 | R19: false | S19: A | T19: false | U19: false | V19: Couldn't get balls through the shooter | W19: 3
A20: TimoS | B20: 10 | C20: B1 | D20: 6413 | E20: H | F20: false | G20: true | H20: true | I20: false | K20: false | L20: false | M20: false | N20: 0 | O20: 0 | P20: 10 | Q20: 70 | R20: false | S20: NA | T20: false | U20: false | V20: Beached on ramp for 1 min. | W20: 3
A21: Joep | B21: 10 | C21: B2 | D21: 2122 | E21: O | F21: false | G21: true | H21: true | I21: true | J21: NA | K21: true | L21: false | M21: false | N21: 0 | O21: 0 | P21: 110 | Q21: 90 | R21: false | S21: NA | T21: false | U21: false | W21: 5
A22: Yannis | B22: 11 | C22: B1 | D22: 3243 | E22: D | F22: false | G22: true | H22: true | I22: true | J22: NA | K22: true | L22: false | M22: flse | O22: E4
A23: Nick | B23: 11 | C23: B2 | D23: 2662 | E23: H | F23: false | G23: true | H23: false | I23: false | K23: false | L23: false | M23: false | N23: 0 | O23: 0 | P23: 0 | R23: false | S23: NA | T23: false | U23: false | V23: Nothing happened, could drive though | W23: 1
A24: LeoV | B24: 11 | C24: B3 | D24: 7425 | E24: H | F24: false | G24: true | H24: true | I24: true | K24: false | L24: false | M24: true | N24: 0 | O24: 0 | P24: 30 | Q24: 43 | R24: true | S24: NA | T24: false | U24: false | V24: Slow in transition between collect and shoot | W24: 3
A25: Yannis | B25: 12 | C25: B2 | D25: 10114 | E25: H | F25: false | G25: true | H25: true | I25: true | J25: A | K25: true | L25: false | M25: false | N25: 10 | O25: 15 | P25: 10 | Q25: 50 | R25: false | S25: A | T25: false | U25: false | W25: 3
A26: LeoV | B26: 12 | C26: B3 | D26: 3224 | E26: O | F26: false | G26: false | H26: false | I26: false | K26: true | L26: false | M26: false | N26: 0 | O26: 15 | P26: 0 | Q26: 60 | R26: false | S26: NA | T26: false | U26: true | V26: Broke and stranded, Slow shooter | W26: 3
A27: LeoV | B27: 13 | C27: R1 | D27: 7333 | E27: O | F27: false | G27: true | H27: true | I27: false | J27: NA | K27: true | L27: true | M27: false | N27: 0 | O27: 0 | P27: 40 | Q27: 55 | R27: false | S27: NA | T27: false | U27: false | V27: Slow shooting and slow positioning during telop | W27: 5
A28: Mil g | B28: 13 | C28: B1 | D28: 7333 | E28: D | F28: false | G28: true | H28: true | I28: false | J28: NA | K28: true | L28: false | M28: false | N28: 0 | O28: 0 | P28: 25 | Q28: 69 | R28: false | S28: NA | T28: false | U28: false | V28: Cancelled auto due to collision with other robot. | W28: 4
A29: Mil G | B29: 12 | C29: B1 | D29: 1410 | E29: D | F29: false | G29: true | H29: false | I29: false | J29: No attempt | K29: true | L29: false | M29: false | N29: 0 | O29: 0 | P29: 0 | Q29: 100 | R29: false | S29: NA | T29: false | U29: false | V29: Was mainly pushing fuel around the field. Started collecting fuel during the last 20 sec of the game. | W29: 5
A30: LeoV | B30: 14 | C30: B3 | D30: 5933 | E30: H | F30: false | G30: false | H30: false | I30: false | J30: NA | K30: true | L30: true | M30: false | N30: 0 | O30: 0 | P30: 15 | Q30: 34 | R30: false | S30: NA | T30: false | U30: true | V30: Slow in precise shooting slow output took his time bad aming | W30: 2
A31: LeoV | B31: 15 | C31: B3 | D31: 7425 | E31: H | F31: false | G31: true | H31: true | I31: false | J31: NA | K31: true | L31: true | M31: true | N31: 0 | O31: 3 | P31: 20 | Q31: 48 | R31: false | S31: NA | T31: false | U31: false | V31: Poor shooter got stuck on balls | W31: 5
A32: LeoV | B32: 17 | C32: B3 | D32: 9501 | E32: O | F32: false | G32: false | H32: true | I32: true | K32: true | L32: true | M32: false | N32: 0 | O32: 0 | P32: 50 | Q32: 83 | R32: false | S32: NA | T32: false | U32: false | V32: Fast and accurate shooting | W32: 5
A33: TimoS | B33: 17 | C33: B2 | D33: 10114 | E33: H | F33: false | G33: true | H33: true | I33: true | J33: L1 | K33: true | L33: false | M33: false | N33: 2 | O33: 0 | P33: 30 | Q33: 71 | R33: false | S33: 1 | T33: false | U33: false | V33: Climber got stuck L1 after auto. Could release itself after 10 sec | W33: 3
A34: Joep | B34: 18 | C34: R1 | D34: 3019 | E34: O | F34: false | G34: true | H34: false | I34: false | J34: NA | K34: true | L34: true | M34: false | N34: 0 | O34: 0 | P34: 10 | Q34: 50 | R34: false | S34: NA | T34: false | U34: false | W34: 3
A35: TimoS | B35: 1 | C35: B2 | D35: 987 | E35: O | F35: false | G35: false | H35: true | I35: true | J35: No attempt | K35: false | L35: false | M35: false | N35: 0 | O35: 0 | P35: 120 | Q35: 30 | R35: false | S35: NA | T35: false | U35: false | V35: Shoots way to hard | W35: 5
A36: LeoV | B36: 18 | C36: B3 | D36: 9059 | E36: H | F36: false | G36: true | H36: false | I36: false | J36: NA | K36: true | L36: false | M36: false | N36: 11 | O36: 0 | P36: 5 | Q36: 4 | R36: false | S36: NA | T36: false | U36: false | V36: Poor shooting | W36: 2
A37: Jippe | B37: 17 | C37: B1 | D37: 1212 | E37: O | F37: false | G37: true | H37: true | I37: false | J37: No attempt | K37: true | L37: false | M37: false | N37: 7 | O37: 3 | P37: 10 | Q37: 1 | R37: false | S37: A | T37: false | U37: false | V37: Intake is very slow | W37: 3
A38: Jippe | B38: 18 | C38: B1 | D38: 2486 | E38: D | F38: false | G38: false | H38: true | I38: true | J38: No attempt | K38: true | L38: false | M38: false | N38: 0 | O38: 0 | P38: 65 | Q38: 45 | R38: true | S38: NA | T38: false | U38: false | W38: 4
A39: Jippe | B39: 19 | C39: B1 | D39: 7333 | E39: D | F39: false | G39: true | H39: true | I39: true | J39: No attempt | K39: true | L39: false | M39: false | N39: 0 | O39: 3 | P39: 0 | Q39: 100 | R39: false | S39: NA | T39: false | U39: false | W39: 4
A40: Jippe | B40: 20 | C40: B1 | D40: 11176 | E40: D | F40: false | G40: true | H40: false | I40: false | J40: No attempt | K40: true | L40: false | M40: false | N40: 12 | O40: 9 | P40: 0 | Q40: 54 | R40: false | S40: NA | T40: false | U40: false | W40: 3
...

Sheet Pit_Input
A1: pit scouter | B1: team name | C1: team_number | D1: weight | E1: min height | F1: width and lenght | G1: hopper balls | H1: drivetrain | I1: Auto start position | J1: auto | K1: climb | L1: pick up | M1: avg cycle time | N1: over bump | O1: under trench | P1: feed from middle | Q1: Auto align | R1: shooting | S1: comments/doubts | T1: Foto | V1: klopt?
A2: Mil G | B2: Sabercat | C2: 4146 | D2: 105 no bum bat | E2: 24 inch unde trench | F2: 26x27inch | G2: 50 | H2: Swerve | I2: Depot | J2: Climb, 8 pre loaded, l1 | K2: L1 | L2: Everwhte | M2: 0 | N2: true | O2: true | P2: true | Q2: true | R2: Both | U2: =T2 -> 0 | V2: TRUE
A3: Mil G | B3: Col robotics | C3: 9059 | D3: 115 | E3: 29.5 | F3: 25.5 | G3: 40 | H3: Swerve | I3: Top, to depot, | J3: Bottom, outpost to human player | K3: No | L3: Ground and human player | M3: 0 | N3: true | O3: false | P3: true | Q3: true | R3: Both | S3: West coast products, design, t 2 lanes, 2 rollers, 2 main lanes, 2 motor powered, pid problems until testing to trouble shoot. Camera»s. | U3: =T3 -> 0 | V3: TRUE
A4: Mil G | B4: Waterford robotics | C4: 3424 | D4: 95 | E4: 21 | F4: 26,28.5 | G4: ? | H4: Swerve | I4: ? | J4: 2 versions, shoot 8 balls pre loaf and collect human player | K4: No | L4: Depot and field | M4: true | N4: true | O4: false | P4: false | Q4: Stationary | S4: 50 feul, 4 roler for spindex, into the shooter, no limelight functions, no auto aim, lineup with the hood, 2/3 balls per second. | U4: =T4 -> 0 | V4: TRUE
A5: Mil g | B5: Waterford robotics | C5: 3245 | D5: 110 | E5: 21.5 | F5: 26.26 | G5: 30-40 | H5: Swerve | I5: Outpost | J5: - | K5: No | L5: Anywhere | M5: 0 | N5: true | O5: true | P5: false | Q5: true | R5: Both | S5: Take for hopper, index the balls, limelight dir autoalign. Geared together motors 2, | U5: =T5 -> 0 | V5: TRUE
A6: Mil g | B6: Pair of dice | C6: 7426 | D6: 112 | E6: 21.5 | F6: 27.27 | G6: 40-50 | H6: Swerve | I6: Outpost | J6: 2 version, middle and shoot Middle , shoot back and climb | K6: L1 | L6: All sides | N6: true | O6: true | P6: false | Q6: true | R6: Both | S6: 3 limelights, alignment , one of sides. | U6: =T6 -> 0 | V6: TRUE
A7: Mil g | B7: Robokrew | C7: 2662 | D7: 79 | E7: 21 inch | F7: 25.28 | G7: 20 | H7: Swerve | J7: Score preload , move to neuttral zone | K7: No | N7: true | O7: true | P7: false | Q7: false | R7: Stationary | S7: Smack down intake, foxed shooter, no climb. Looks like a fish, since they are a fish | U7: =#REF! -> #REF! | V7: TRUE
A8: Maud R | B8: 10114 phantom talows | C8: 10114 | D8: 112 | E8: - | F8: 27.27 | G8: 20 | H8: Swerve | J8: Level 1 climb | K8: L1 | M8: 7 | N8: ? | O8: ? | P8: false | Q8: true | R8: true | U8: =T8 -> 0 | V8: TRUE
A9: Maud R | B9: Broncobots | C9: 991 | D9: 109 | E9: 21 | F9: 30.52 | G9: 55 | H9: Swerve | I9: Outpost | J9: Middle shoot balls goes human player | K9: - | L9: Overall | M9: 15 | N9: true | O9: true | P9: true | Q9: true | R9: Driving | U9: =T9 -> 0 | V9: TRUE
A10: Maud R | B10: Launchteam | C10: 6362 | D10: 114 | E10: 30 | F10: 30.25 | G10: 80 | H10: Swerve | I10: Hub | J10: Several ones shoot preload by all of them | K10: L1 | L10: From the ground | M10: 20 | N10: true | O10: false | P10: true | Q10: true | R10: Stationary | U10: =T10 -> 0 | V10: TRUE
A11: Maud R | B11: Dragon Hunters | C11: 10380 | D11: 107 | E11: 22 | F11: 27.27 | G11: 45 | H11: Swerve | I11: Deptt | J11: Le | M11: true | N11: false | O11: true | P11: true | Q11: false | R11: Stationary | S11: Triple shooter, extendable intake | U11: =T11 -> 0 | V11: TRUE
A12: Maud R | B12: Hamilton Microbots | C12: 698 | D12: 113 | E12: 30 | F12: 28.28 | G12: 30 | H12: Swerve | I12: Hub | J12: Shoot preload | K12: - | L12: Ground and autpost | M12: 23 | N12: true | O12: true | P12: true | Q12: true | R12: Stationary | S12: Adjustable hood, triple shooter | U12: =T12 -> 0 | V12: TRUE
A13: Maud R | B13: Desert storm | C13: 10988 | D13: 94 | E13: 22.8 | F13: 26.28 | G13: 40 | H13: Swerve | I13: Depot | J13: With preload to outpost and then shoot that | L13: Ground, outpost | M13: 15 | N13: true | O13: false | P13: false | Q13: true | R13: Stationary | U13: =T13 -> 0 | V13: TRUE
A14: Maud R | B14: RoboRabits | C14: 11176 | D14: 79 | E14: 29 | F14: 27,5,27,5 | G14: 10 | H14: Swerve | I14: Hub | J14: Shoot preload | K14: - | L14: Ground and outpost | N14: true | O14: false | P14: true | Q14: false | R14: Stationary | S14: Double shooter | U14: =T14 -> 0 | V14: TRUE
A15: Maud R | B15: Team Love | C15: 10905 | D15: 105 | E15: 22 | F15: 26.28 | G15: 45 | H15: Swerve | I15: - | J15: - | L15: Only human player | N15: true | O15: true | P15: false | Q15: false | R15: Stationary | S15: Intake is being build, double shooter, geen auto | U15: =T15 -> 0 | V15: TRUE
A16: Maud R | B16: Crash test dummies | C16: 10506 | D16: 66 | F16: 24.38 | G16: 20 | H16: Mecanum | I16: Hub | J16: Shoot preload | L16: Only ground | N16: true | O16: true | P16: true | Q16: false | R16: Stationary | S16: Intake fully 3d printer | V16: TRUE
A17: Maud R | B17: Westwood robotics | C17: 2478 | D17: 100 | E17: 22 | F17: 27.27 | G17: 55 | H17: Swerve | I17: Outpost | J17: Middle- shoot preload, Trench- picks up balls and shoots | K17: - | L17: Ground and human player | M17: 12 | N17: false | O17: true | P17: true | Q17: true | R17: Stationary | S17: Double shooter | V17: TRUE
A18: Mil g | B18: Firebird robotics | C18: 3019 | D18: 98 | E18: 26 | F18: 20.26 | G18: 20+ | H18: Swerve | I18: Depot | J18: No yet | K18: No | L18: All sides | N18: false | O18: true | P18: true | Q18: true | R18: Stationary | S18: Swerve, afjustabel shooter, roller tank, intake, movable intake, feeder to shooter, camera behind intake driver camera for intake. | V18: TRUE
A19: Mil G | B19: Aztech | C19: 6479 | D19: 103 | E19: 22 | F19: 27.27 | G19: 25 | H19: Swerve | I19: Depot | J19: Shoot preload, neutral, intake and shoot | K19: L1 | L19: Neutral, to aligens | M19: 7 | N19: true | O19: true | P19: true | Q19: true | R19: Stationary | V19: TRUE
A20: Mil g | B20: High rollers | C20: 987 | D20: 108 | E20: 22.3 | F20: 30.23 | G20: 33 | H20: Swerve | I20: Outpost | J20: Swipes, 25- 40 balls, shooting | K20: L3 | L20: Aligens and neutral | N20: true | O20: true | P20: true | Q20: true | R20: Both | S20: Issues, trail and error, seperate turrets, 1 gets jammed. Climbing is special thing. | V20: TRUE
A21: Mil g | B21: DOF | C21: 6413 | D21: 109 | E21: 24 | F21: 27.27 | G21: 41 | H21: Swerve | I21: Hub | J21: Shooting infront of hub, Sweep from middle and shoot, | K21: No | L21: Everywhere | M21: 15 | N21: true | O21: false | P21: true | Q21: false | R21: Stationary | S21: 41 balls, 3 ball fixed shooter, over the tamp, infront of the hub. Horizontal seperated from shooting, one motor fail, no shooter. | V21: TRUE
A22: Mil g | B22: Bulldogs | C22: 60 | D22: 104 | E22: 30 | F22: 28.26 | G22: 20 | H22: Tank | I22: Depot | J22: Pre load empty, over bump, intake more | K22: No | L22: Both, able for defence | M22: 0 | N22: true | O22: false | P22: true | Q22: true | R22: Stationary | S22: Pneumatics speed gearboxes, motorized, steel fly wheel, intake kit box, dropped the shooter, | V22: TRUE
A23: Mil g | B23: Sidereal envoy | C23: 9501 | D23: 103 | E23: 22 | F23: 27.5,25.9 | G23: 35 | H23: Swerve | I23: Depot | J23: Neutral, collect en shoot and depot and shoot | K23: No | L23: Everywhere | M23: 10 | N23: true | O23: true | P23: true | Q23: false | R23: Stationary | S23: Index shooter intake, adjust angle, indepentand. | V23: TRUE
A24: Mil g | B24: Sidereal envoy | C24: 9501 | D24: 103 | E24: 22 | F24: 27.5,25.9 | G24: 35 | H24: Swerve | I24: Depot | J24: Neutral, collect en shoot and depot and shoot | K24: No | L24: Everywhere | M24: 10 | N24: true | O24: true | P24: true | Q24: false | R24: Stationary | S24: Index shooter intake, adjust angle, indepentand. | V24: TRUE
A25: Nick | B25: Robodawgs 3D | C25: 244 | D25: 70/80 pounds | E25: 28 inch | F25: 27x27 inch | G25: 60 | H25: Swerve | I25: Depot | J25: Left or right, just shoot | K25: 5 | L25: nope????? | M25: 0 | N25: true | O25: false | P25: true | Q25: false | R25: Stationary | V25: TRUE
A26: Nick | B26: Robodawgs 3D | C26: 288 | D26: 94 pounds | E26: 30 inch | F26: 27x27 inch | G26: 60 | H26: Swerve | I26: Depot | J26: Left or right, just shoot | K26: None | L26: None during auto ?????? | M26: 15 | N26: true | O26: false | P26: true | Q26: false | R26: Stationary | V26: TRUE
A27: Nick | B27: Paradise | C27: 1165 | D27: 104 pounds | E27: 20.5 inch | F27: 24.5x29.5 | G27: 30 | H27: Swerve | I27: Depot | J27: Left or right, just shoot | K27: Nope | L27: Ground and outpost | M27: 0 | N27: true | O27: true | P27: true | Q27: true | R27: Driving | S27: No cycle test, prefer trench | V27: FALSE
A28: Nick | B28: Turbotics | C28: 2080 | D28: 97.3pounds | E28: 24.75 inch | F28: 27x27 inch | G28: 15 | H28: Swerve | I28: Hub | J28: No auto, starts wherever | K28: Nope | L28: Ground, outpost | M28: 11 | N28: true | O28: false | P28: true | Q28: false | R28: Stationary | V28: FALSE
A29: Nick | B29: Coconuts | C29: 2486 | D29: 111.3 pounds | E29: 21.75 inch | F29: 27x27 inch | G29: 50/60 | H29: Swerve | I29: Depot | J29: Goes to Middle to outpost | K29: Nope | L29: Ground and outposts | M29: 10 | N29: true | O29: false | P29: true | Q29: true | R29: Stationary | V29: FALSE
A30: Nick | B30: The kraken | C30: 1410 | D30: 115 pounds | E30: 21 - 22.2 inch | F30: 27x27 inch | G30: 12 | H30: Swerve | I30: Hub | J30: Can do hub and bump | K30: Nope | L30: Ground, doesnt take from outposts but can | M30: 15 | N30: true | O30: true | P30: true | Q30: false | R30: Stationary | V30: FALSE
A31: Nick | B31: Sentinels | C31: 1212 | D31: 111 pounds | E31: 29.5 inch | F31: 21 x 31.5 inch | G31: 30-40 | H31: Swerve | I31: Hub | J31: Shoots | K31: Nope | L31: Middle | M31: 25 | N31: true | O31: false | P31: true | Q31: true | R31: Stationary | V31: FALSE
A32: Nick | B32: Formosa | C32: 11479 | D32: 98 pounds | E32: No measure | F32: 67 cm | G32: 30-40 | H32: Swerve | I32: Depot | J32: Left or right, just shoot Goes to Middle and back to shoot, goes back to Middle to feed | K32: no | L32: All sides | M32: 10 | N32: false | O32: true | P32: true | Q32: true | R32: Stationary | V32: FALSE
A33: Nick | B33: Toe due samurai | C33: 10933 | D33: 114.4 pounds | E33: No measure, close to max | F33: 27x27 inch | G33: 10 | H33: Swerve | I33: Hub | J33: Starts anywhere, no auto | K33: Nope | L33: Anywhere | M33: 0 | N33: true | O33: true | P33: true | Q33: false | R33: Both | S33: Mostly plays defence | V33: FALSE
A34: Nick | B34: Launch tean | C34: 6352 | D34: 114 pounds | E34: 30inch | F34: 30x25 inch | G34: 60-80 | H34: Swerve | I34: Hub | J34: Bump either side | K34: Lvl 1 | L34: Ground pickup | M34: 20 | N34: true | O34: false | P34: true | Q34: true | R34: Stationary | V34: FALSE
V35: FALSE
V36: FALSE
V37: FALSE
V38: FALSE
V39: FALSE
V40: FALSE
...

Sheet Pit checklist
A1: 60 | B1: =IF(EXACT(A1,IFERROR(VLOOKUP(A1,Pit_Input!C:S,1,FALSE),0)),"Aanwezig","Afwezig") -> Aanwezig | C1: 6413 | D1: =IF(EXACT(C1,IFERROR(VLOOKUP(C1,Pit_Input!C:S,1,FALSE),0)),"Aanwezig","Afwezig") -> Aanwezig
A2: 244 | B2: =IF(EXACT(A2,IFERROR(VLOOKUP(A2,Pit_Input!C:S,1,FALSE),0)),"Aanwezig","Afwezig") -> Aanwezig | C2: 6479 | D2: =IF(EXACT(C2,IFERROR(VLOOKUP(C2,Pit_Input!C:S,1,FALSE),0)),"Aanwezig","Afwezig") -> Aanwezig
A3: 288 | B3: =IF(EXACT(A3,IFERROR(VLOOKUP(A3,Pit_Input!C:S,1,FALSE),0)),"Aanwezig","Afwezig") -> Aanwezig | C3: 6833 | D3: =IF(EXACT(C3,IFERROR(VLOOKUP(C3,Pit_Input!C:S,1,FALSE),0)),"Aanwezig","Afwezig") -> Afwezig
A4: 698 | B4: =IF(EXACT(A4,IFERROR(VLOOKUP(A4,Pit_Input!C:S,1,FALSE),0)),"Aanwezig","Afwezig") -> Aanwezig | C4: 7333 | D4: =IF(EXACT(C4,IFERROR(VLOOKUP(C4,Pit_Input!C:S,1,FALSE),0)),"Aanwezig","Afwezig") -> Afwezig
A5: 987 | B5: =IF(EXACT(A5,IFERROR(VLOOKUP(A5,Pit_Input!C:S,1,FALSE),0)),"Aanwezig","Afwezig") -> Aanwezig | C5: 7425 | D5: =IF(EXACT(C5,IFERROR(VLOOKUP(C5,Pit_Input!C:S,1,FALSE),0)),"Aanwezig","Afwezig") -> Afwezig
A6: 991 | B6: =IF(EXACT(A6,IFERROR(VLOOKUP(A6,Pit_Input!C:S,1,FALSE),0)),"Aanwezig","Afwezig") -> Aanwezig | C6: 7426 | D6: =IF(EXACT(C6,IFERROR(VLOOKUP(C6,Pit_Input!C:S,1,FALSE),0)),"Aanwezig","Afwezig") -> Aanwezig
A7: 996 | B7: =IF(EXACT(A7,IFERROR(VLOOKUP(A7,Pit_Input!C:S,1,FALSE),0)),"Aanwezig","Afwezig") -> Afwezig | C7: 7755 | D7: =IF(EXACT(C7,IFERROR(VLOOKUP(C7,Pit_Input!C:S,1,FALSE),0)),"Aanwezig","Afwezig") -> Afwezig
A8: 1165 | B8: =IF(EXACT(A8,IFERROR(VLOOKUP(A8,Pit_Input!C:S,1,FALSE),0)),"Aanwezig","Afwezig") -> Aanwezig | C8: 8012 | D8: =IF(EXACT(C8,IFERROR(VLOOKUP(C8,Pit_Input!C:S,1,FALSE),0)),"Aanwezig","Afwezig") -> Afwezig
A9: 1212 | B9: =IF(EXACT(A9,IFERROR(VLOOKUP(A9,Pit_Input!C:S,1,FALSE),0)),"Aanwezig","Afwezig") -> Aanwezig | C9: 8717 | D9: =IF(EXACT(C9,IFERROR(VLOOKUP(C9,Pit_Input!C:S,1,FALSE),0)),"Aanwezig","Afwezig") -> Afwezig
A10: 1410 | B10: =IF(EXACT(A10,IFERROR(VLOOKUP(A10,Pit_Input!C:S,1,FALSE),0)),"Aanwezig","Afwezig") -> Aanwezig | C10: 9059 | D10: =IF(EXACT(C10,IFERROR(VLOOKUP(C10,Pit_Input!C:S,1,FALSE),0)),"Aanwezig","Afwezig") -> Aanwezig
A11: 1828 | B11: =IF(EXACT(A11,IFERROR(VLOOKUP(A11,Pit_Input!C:S,1,FALSE),0)),"Aanwezig","Afwezig") -> Afwezig | C11: 9091 | D11: =IF(EXACT(C11,IFERROR(VLOOKUP(C11,Pit_Input!C:S,1,FALSE),0)),"Aanwezig","Afwezig") -> Afwezig
A12: 2080 | B12: =IF(EXACT(A12,IFERROR(VLOOKUP(A12,Pit_Input!C:S,1,FALSE),0)),"Aanwezig","Afwezig") -> Aanwezig | C12: 9501 | D12: =IF(EXACT(C12,IFERROR(VLOOKUP(C12,Pit_Input!C:S,1,FALSE),0)),"Aanwezig","Afwezig") -> Aanwezig
... A28: 5933 | B28: =IF(EXACT(A28,IFERROR(VLOOKUP(A28,Pit_Input!C:S,1,FALSE),0)),"Aanwezig","Afwezig") -> Afwezig | C28: 11479 | D28: =IF(EXACT(C28,IFERROR(VLOOKUP(C28,Pit_Input!C:S,1,FALSE),0)),"Aanwezig","Afwezig") -> Aanwezig
A29: 6352 | B29: =IF(EXACT(A29,IFERROR(VLOOKUP(A29,Pit_Input!C:S,1,FALSE),0)),"Aanwezig","Afwezig") -> Aanwezig

Sheet Per_Team
A1: Team Number | B1: Team name | Q1: Pit scouting | S1: Avg alles
A2: 3944 | B2: =Y4 -> 0 | Q2: Weight | R2: =AA4 -> 0 | S2: =AVERAGE(Pit_Input!D2:D99) -> 101.72727
Q3: Min Height | R3: =AB4 -> 0 | S3: =AVERAGE(Pit_Input!E2:E99) -> 24.25625 | X3: pit scouter | Y3: team name | Z3: team_number | AA3: weight | AB3: min height | AC3: max height | AD3: breedte en lengte | AE3: hopper balls | AF3: drivetrain | AG3: Auto start positie | AH3: auto | AI3: climb | AJ3: pick up | AK3: avg cycle time | AL3: over bump | AM3: onder balk | AN3: feed from middle | AO3: Auto align | AP3: Hoe schieten | AQ3: comments/doubts | AR3: Foto
A4: Procent hit | B4: Climb | C4: amount | E4: Start where | F4: amount | H4: Pick up | I4: amount | K4: Auto | L4: procent | N4: Balls | Q4: Max height | R4: =AC4 -> 0 | S4: =AVERAGE(Pit_Input!#REF!) -> #REF! | X4: {=_xlfn._xlws.FILTER(Tabel2[], Tabel2[team_number]=A2, "Geen resultaten")} -> Geen resultaten
A5: =AVERAGE(Q32:Q99)/100 -> 0.42 | B5: L1 | C5: =COUNTIF(S32:S99,"L1") -> 0 | E5: Depot | F5: =COUNTIF(E32:E99, "D") -> 1 | H5: Ground | I5: =COUNTIF(K32:K105, "true") -> 1 | K5: Moved | L5: =COUNTIF(H32:H99,"true")/COUNT(B32:B99) -> 0 | N5: min | O5: {=MIN(IF(AB11:AB30>0, AB11:AB30))} -> 2 | Q5: Hopperballs | R5: =AE4 -> 0 | S5: =AVERAGE(Pit_Input!G2:G99) -> 35.44
B6: L2 | C6: =COUNTIF(S32:S99,"L2") -> 0 | E6: Hub | F6: =COUNTIF(E32:E99, "H") -> 1 | H6: Human Player | I6: =COUNTIF(L32:L99, "true") -> 0 | K6: Climb | L6: =COUNTIF(J32:J99,"true")/COUNT(B32:B99) -> 0 | N6: avg | O6: =AVERAGE(AB11:AB84) -> 3.25 | Q6: Drivetrain | R6: =AF4 -> 0
B7: L3 | C7: =COUNTIF(S32:S99,"L3") -> 0 | E7: Outpost | F7: =COUNTIF(E32:E99, "O") -> 2 | H7: Depot | I7: =COUNTIF(M32:M99,"true") -> 0 | K7: Shoot | L7: =COUNTIF(I32:I99,"true")/COUNT(B32:B99) -> 0 | N7: max | O7: =MAX(AB11:AB84) -> 8 | Q7: Climb | R7: =AI4 -> 0
B8: Attempt | C8: =COUNTIF(S32:S99,"A") -> 0 | K8: Gem | L8: =AVERAGE(I32:I46) -> #DIV/0! | Q8: Pickup | R8: =AJ4 -> 0
B9: No Attempt | C9: =COUNTIF(S32:S99,"NA") -> 3 | K9: max | L9: =MAX(I32:I51) -> 0 | Q9: cycle time | R9: =AK4 -> 0 | S9: =AVERAGE(Pit_Input!M2:M99) -> 10
A10: avg balls per match | Q10: over bump | R10: =AL4 -> 0 | AB10: som per match
Q11: under trench | R11: =AM4 -> 0 | S11: =COUNTIF(Pit_Input!O2:O63,1) -> 0 | T11: /56 | Y11: {=IF(N32:P64="","",N32:P64)} -> 0 | Z11: 0 | AA11: 0 | AB11: =IF(COUNT(Y11:AA11)=0,"",SUM(Y11:AA11)) -> 0
Q12: feed middle | R12: =AN4 -> 0 | S12: =COUNTIF(Pit_Input!P2:P62,1) -> 0 | T12: /56 | Y12: 2 | Z12: 0 | AA12: 0 | AB12: =IF(COUNT(Y12:AA12)=0,"",SUM(Y12:AA12)) -> 2
Q13: auto align | R13: =AO4 -> 0 | S13: =COUNTIF(Pit_Input!Q2:Q62,1) -> 0 | T13: /56 | Y13: 3 | Z13: 0 | AA13: 0 | AB13: =IF(COUNT(Y13:AA13)=0,"",SUM(Y13:AA13)) -> 3
A14: =AVERAGE(AB11:AB60) -> 3.25 | R14: =AP4 -> 0 | Y14: 2 | Z14: 6 | AA14: 0 | AB14: =IF(COUNT(Y14:AA14)=0,"",SUM(Y14:AA14)) -> 8
AB15: =IF(COUNT(Y15:AA15)=0,"",SUM(Y15:AA15))
AB16: =IF(COUNT(Y16:AA16)=0,"",SUM(Y16:AA16))
AB17: =IF(COUNT(Y17:AA17)=0,"",SUM(Y17:AA17))
B18: most | C18: =INDEX(B5:B7,MATCH(MAX(C5:C7),C5:C7,0)) -> L1 | E18: most | F18: =INDEX(E5:E7,MATCH(MAX(F5:F7),F5:F7,0)) -> Outpost | H18: most | I18: =INDEX(H5:H7,MATCH(MAX(I5:I7),I5:I7,0)) -> Ground | AB18: =IF(COUNT(Y18:AA18)=0,"",SUM(Y18:AA18))
AB19: =IF(COUNT(Y19:AA19)=0,"",SUM(Y19:AA19))
B20: Comments | J20: Comments Pit | AB20: =IF(COUNT(Y20:AA20)=0,"",SUM(Y20:AA20))
B21: {=IFERROR(_xlfn._xlws.FILTER(V32:V99, (V32:V99<>"") * (ISNUMBER(V32:V99)=FALSE)), "")} -> Mainly focused on ball feeding | J21: {=IFERROR(_xlfn._xlws.FILTER(AQ4:AQ71, (AQ4:AQ71<>"") * (ISNUMBER(AQ4:AQ71)=FALSE)), "")} | AB21: =IF(COUNT(Y21:AA21)=0,"",SUM(Y21:AA21))
AB22: =IF(COUNT(Y22:AA22)=0,"",SUM(Y22:AA22))
AB23: =IF(COUNT(Y23:AA23)=0,"",SUM(Y23:AA23))
AB24: =IF(COUNT(Y24:AA24)=0,"",SUM(Y24:AA24))
AB25: =IF(COUNT(Y25:AA25)=0,"",SUM(Y25:AA25))
AB26: =IF(COUNT(Y26:AA26)=0,"",SUM(Y26:AA26))
AB27: =IF(COUNT(Y27:AA27)=0,"",SUM(Y27:AA27))
AB28: =IF(COUNT(Y28:AA28)=0,"",SUM(Y28:AA28))
AB29: =IF(COUNT(Y29:AA29)=0,"",SUM(Y29:AA29))
AB30: =IF(COUNT(Y30:AA30)=0,"",SUM(Y30:AA30))
A31: Scouter Initials | B31: Match Number | C31: Robot | D31: Team Number | E31: Starting Position | F31: No Show | G31: Preload | H31: Moved? | I31: Shoot | J31: Climbing | K31: PickUp Ground | L31: PickUP Human Player | M31: PickUp Depot | N31: +1 | O31: +3 | P31: +5 | Q31: Amount in Hub | R31: Defence/ to other side | S31: End Position | T31: Died? | U31: Tipped/Fell Over? | V31: Comments | W31: driver skill | AB31: =IF(COUNT(Y31:AA31)=0,"",SUM(Y31:AA31))
A32: {=_xlfn._xlws.FILTER(Tabel1[], Tabel1[Team Number]=A2, "Geen resultaten")} -> LeoV | B32: 5 | C32: B1 | D32: 3944 | E32: D | F32: false | G32: true | H32: false | I32: false | J32: NA | K32: false | L32: false | M32: false | N32: 0 | O32: 0 | P32: 0 | Q32: 1 | R32: false | S32: NA | T32: true | U32: false | V32: 0 | W32: 3 | AB32: =IF(COUNT(Y32:AA32)=0,"",SUM(Y32:AA32))
A33: JV | B33: 50 | C33: R3 | D33: 3944 | E33: H | F33: false | G33: true | H33: false | I33: false | J33: NA | K33: false | L33: false | M33: false | N33: 2 | O33: 0 | P33: 0 | Q33: 20 | R33: false | S33: NA | T33: false | U33: false | V33: Mainly focused on ball feeding | W33: 5 | AB33: =IF(COUNT(Y33:AA33)=0,"",SUM(Y33:AA33))
